Workbook

Sheet README
A1: Workforce Intelligence - Employee Dataset (fictional)
A2: Company: Nimbus Technologies. As-of date 15 Oct 2026. 120 employees, 7 projects. Built for HackAttack - Workforce Intelligence.
A4: Sheets
A5: Employee_Master - HR-style employee records. Allocated Hrs, Utilization, Available Hrs and Workload Status are formulas over Allocations.
A6: Skill_Matrix - employee x skill proficiency grid (1 beginner ... 5 expert). Blank = no skill recorded.
A7: Allocations - who works on which project, hours per week. Movable = Yes means task can be reassigned.
A8: Projects / Project_Requirements - 6 active projects and 1 planning project (P7). Training_Catalog and Skills - reference lists.
A10: Rules: Utilization = allocated hrs / capacity hrs. Overloaded > 100%. Underutilized < 50%. Otherwise Healthy.
A11: Scenario A: P7 Customer Churn Analytics needs Python L4, Cloud L4, Data Analytics L4, SQL L3, Spark L3, Power BI L2. Spark is a deliberate gap (nobody above L2).
A12: Scenario B: several overloaded employees share skills with underutilized employees, so rebalancing is possible.
A14: All names, emails, managers, clients and courses are fictional. Current Projects column is a text snapshot of Allocations.

Sheet Employee_Master
A1: Employee ID | B1: Full Name | C1: Email | D1: Department | E1: Designation | F1: Grade | G1: Reporting Manager | H1: Date of Joining | I1: Total Experience (Yrs) | J1: Work Location | K1: Work Mode | L1: Employment Type | M1: Highest Qualification | N1: Primary Skills | O1: Secondary Skills | P1: Certifications | Q1: Performance Rating (1-5) | R1: Capacity Hrs/Week | S1: Allocated Hrs/Week | T1: Utilization | U1: Available Hrs/Week | V1: Workload Status | W1: Current Projects | X1: Leave Start | Y1: Leave End | Z1: Last Training Completed
A2: NT-1001 | B2: Pooja Mishra | C2: pooja.mishra@nimbustech.example | D2: Quality Assurance | E2: Senior QA Engineer | F2: L3 | G2: Aarav Teja | H2: 45902 | I2: 7 | J2: Chennai | K2: Onsite | L2: Full-time | M2: M.Tech Computer Science | N2: Testing & QA (L5), SQL (L3), JavaScript (L2) | P2: ISTQB Foundation Level | Q2: 4 | R2: 40 | S2: =SUMIFS(Allocations!$G$2:$G$274,Allocations!$B$2:$B$274,A2) -> 32 | T2: =S2/R2 -> 0.8 | U2: =R2-S2 -> 8 | V2: =IF(T2>1,"Overloaded",IF(T2<0.5,"Underutilized","Healthy")) -> Healthy | W2: Hospital Appointment Portal (15h); HR Analytics Dashboard (17h)
A3: NT-1002 | B3: Varun Teja | C3: varun.teja@nimbustech.example | D3: Quality Assurance | E3: QA Engineer | F3: L2 | G3: Aarav Teja | H3: 45363 | I3: 3 | J3: Pune | K3: Onsite | L3: Full-time | M3: B.Sc Computer Science | N3: Testing & QA (L5), JavaScript (L3), SQL (L2) | Q3: 3 | R3: 40 | S3: =SUMIFS(Allocations!$G$2:$G$274,Allocations!$B$2:$B$274,A3) -> 34 | T3: =S3/R3 -> 0.85 | U3: =R3-S3 -> 6 | V3: =IF(T3>1,"Overloaded",IF(T3<0.5,"Underutilized","Healthy")) -> Healthy | W3: Hospital Appointment Portal (21h); Logistics Fleet Tracker App (13h)
A4: NT-1003 | B4: Nithya Kamath | C4: nithya.kamath@nimbustech.example | D4: Engineering | E4: Frontend Developer | F4: L2 | G4: Charan Hegde | H4: 46041 | I4: 4 | J4: Mumbai | K4: Hybrid | L4: Full-time | M4: B.Tech Information Technology | N4: React (L5), UI/UX Design (L4), JavaScript (L3) | O4: Testing & QA (L3) | Q4: 4 | R4: 40 | S4: =SUMIFS(Allocations!$G$2:$G$274,Allocations!$B$2:$B$274,A4) -> 32 | T4: =S4/R4 -> 0.8 | U4: =R4-S4 -> 8 | V4: =IF(T4>1,"Overloaded",IF(T4<0.5,"Underutilized","Healthy")) -> Healthy | W4: Hospital Appointment Portal (8h); Logistics Fleet Tracker App (24h) | Z4: Spark Performance Tuning (Jul 2026)
A5: NT-1004 | B5: Akash Jain | C5: akash.jain@nimbustech.example | D5: Engineering | E5: Frontend Developer | F5: L2 | G5: Charan Hegde | H5: 44832 | I5: 4 | J5: Pune | K5: Hybrid | L5: Full-time | M5: B.E. Electronics & Communication | N5: JavaScript (L5), React (L5), UI/UX Design (L3) | O5: Testing & QA (L3) | Q5: 3 | R5: 40 | S5: =SUMIFS(Allocations!$G$2:$G$274,Allocations!$B$2:$B$274,A5) -> 24 | T5: =S5/R5 -> 0.6 | U5: =R5-S5 -> 16 | V5: =IF(T5>1,"Overloaded",IF(T5<0.5,"Underutilized","Healthy")) -> Healthy | W5: Hospital Appointment Portal (5h); Logistics Fleet Tracker App (19h) | X5: 46346 | Y5: 46351 | Z5: Python for Production Systems (Sep 2026)
A6: NT-1005 | B6: Harsha Kapoor | C6: harsha.kapoor@nimbustech.example | D6: Engineering | E6: Senior Full-Stack Developer | F6: L3 | G6: Charan Hegde | H6: 44458 | I6: 5 | J6: Bengaluru | K6: Onsite | L6: Full-time | M6: B.E. Information Science | N6: JavaScript (L5), React (L5), Node.js (L5) | O6: SQL (L3), Docker & Kubernetes (L2), DevOps & CI/CD (L2) | Q6: 2 | R6: 40 | S6: =SUMIFS(Allocations!$G$2:$G$274,Allocations!$B$2:$B$274,A6) -> 34 | T6: =S6/R6 -> 0.85 | U6: =R6-S6 -> 6 | V6: =IF(T6>1,"Overloaded",IF(T6<0.5,"Underutilized","Healthy")) -> Healthy | W6: Logistics Fleet Tracker App (17h); Hospital Appointment Portal (17h) | Z6: Data Analytics with Python and SQL (Sep 2026)
A7: NT-1006 | B7: Naveen Prasad | C7: naveen.prasad@nimbustech.example | D7: Platform | E7: Lead DevOps Engineer | F7: L4 | G7: Pooja Narayan | H7: 46176 | I7: 10 | J7: Bengaluru | K7: Hybrid | L7: Full-time | M7: B.Tech Information Technology | N7: DevOps & CI/CD (L5), Docker & Kubernetes (L4), Cloud Computing (AWS/Azure) (L4) | O7: Cybersecurity (L4), Python (L2), Data Analytics (L2) | P7: HashiCorp Terraform Associate; CEH | Q7: 3 | R7: 40 | S7: =SUMIFS(Allocations!$G$2:$G$274,Allocations!$B$2:$B$274,A7) -> 28 | T7: =S7/R7 -> 0.7 | U7: =R7-S7 -> 12 | V7: =IF(T7>1,"Overloaded",IF(T7<0.5,"Underutilized","Healthy")) -> Healthy | W7: Cloud Migration - Legacy ERP (10h); Fintech Fraud Alerts (6h); Logistics Fleet Tracker App (12h) | Z7: Apache Spark Essentials for Data Engineers (Mar 2026)
A8: NT-1007 | B8: Pallavi Tiwari | C8: pallavi.tiwari@nimbustech.example | D8: Engineering | E8: Backend Engineer | F8: L2 | G8: Charan Hegde | H8: 45172 | I8: 3 | J8: Chennai | K8: Hybrid | L8: Full-time | M8: B.Sc Computer Science | N8: Python (L3), SQL (L3), Node.js (L3) | O8: Cloud Computing (AWS/Azure) (L3), Docker & Kubernetes (L2), Power BI / Tableau (L2), Testing & QA (L1) | Q8: 4 | R8: 40 | S8: =SUMIFS(Allocations!$G$2:$G$274,Allocations!$B$2:$B$274,A8) -> 32 | T8: =S8/R8 -> 0.8 | U8: =R8-S8 -> 8 | V8: =IF(T8>1,"Overloaded",IF(T8<0.5,"Underutilized","Healthy")) -> Healthy | W8: Retail Demand Forecasting (4h); Logistics Fleet Tracker App (14h); Hospital Appointment Portal (14h) | Z8: Test Automation with Playwright (Dec 2025)
A9: NT-1008 | B9: Uday Shenoy | C9: uday.shenoy@nimbustech.example | D9: Engineering | E9: Frontend Developer | F9: L2 | G9: Charan Hegde | H9: 45144 | I9: 3 | J9: Hyderabad | K9: Onsite | L9: Full-time | M9: M.Tech Computer Science | N9: JavaScript (L5), React (L5), UI/UX Design (L3) | O9: Testing & QA (L3), Machine Learning (L2) | Q9: 4 | R9: 40 | S9: =SUMIFS(Allocations!$G$2:$G$274,Allocations!$B$2:$B$274,A9) -> 28 | T9: =S9/R9 -> 0.7 | U9: =R9-S9 -> 12 | V9: =IF(T9>1,"Overloaded",IF(T9<0.5,"Underutilized","Healthy")) -> Healthy | W9: Hospital Appointment Portal (16h); Logistics Fleet Tracker App (5h); Retail Demand Forecasting (7h) | Z9: TypeScript for JavaScript Developers (Jan 2026)
A10: NT-1009 | B10: Pooja Narayan | C10: pooja.narayan@nimbustech.example | D10: Platform | E10: Principal DevOps Engineer | F10: L5 | G10: Rajesh Khanna (VP Delivery) | H10: 45753 | I10: 12 | J10: Pune | K10: Onsite | L10: Full-time | M10: B.E. Electronics & Communication | N10: DevOps & CI/CD (L5), Docker & Kubernetes (L3), Cloud Computing (AWS/Azure) (L3) | O10: Cybersecurity (L3), Python (L2) | Q10: 3 | R10: 40 | S10: =SUMIFS(Allocations!$G$2:$G$274,Allocations!$B$2:$B$274,A10) -> 32 | T10: =S10/R10 -> 0.8 | U10: =R10-S10 -> 8 | V10: =IF(T10>1,"Overloaded",IF(T10<0.5,"Underutilized","Healthy")) -> Healthy | W10: Cloud Migration - Legacy ERP (8h); Fintech Fraud Alerts (18h); Logistics Fleet Tracker App (6h)
A11: NT-1010 | B11: Charan Hegde | C11: charan.hegde@nimbustech.example | D11: Engineering | E11: Principal Backend Engineer | F11: L5 | G11: Rajesh Khanna (VP Delivery) | H11: 45097 | I11: 12 | J11: Chennai | K11: Hybrid | L11: Full-time | M11: B.Tech Information Technology | N11: Node.js (L4), Python (L3), SQL (L3) | O11: Docker & Kubernetes (L3), Cloud Computing (AWS/Azure) (L2), Testing & QA (L2) | Q11: 4 | R11: 40 | S11: =SUMIFS(Allocations!$G$2:$G$274,Allocations!$B$2:$B$274,A11) -> 36 | T11: =S11/R11 -> 0.9 | U11: =R11-S11 -> 4 | V11: =IF(T11>1,"Overloaded",IF(T11<0.5,"Underutilized","Healthy")) -> Healthy | W11: Hospital Appointment Portal (5h); Retail Demand Forecasting (31h) | Z11: Modern React Patterns (Jan 2026)
A12: NT-1011 | B12: Divya Menon | C12: divya.menon@nimbustech.example | D12: Data & Analytics | E12: Senior Data Scientist | F12: L3 | G12: Charan Jain | H12: 45870 | I12: 7 | J12: Bengaluru | K12: Onsite | L12: Full-time | M12: M.Tech Computer Science | N12: Python (L4), Data Analytics (L4), SQL (L4) | O12: Machine Learning (L3), Power BI / Tableau (L3) | P12: PCEP - Certified Entry-Level Python Programmer; Oracle SQL Associate | Q12: 3 | R12: 40 | S12: =SUMIFS(Allocations!$G$2:$G$274,Allocations!$B$2:$B$274,A12) -> 50 | T12: =S12/R12 -> 1.25 | U12: =R12-S12 -> -10 | V12: =IF(T12>1,"Overloaded",IF(T12<0.5,"Underutilized","Healthy")) -> Overloaded | W12: HR Analytics Dashboard (20h); Retail Demand Forecasting (18h); Fintech Fraud Alerts (12h) | Z12: Python Fundamentals Bootcamp (Jan 2026)
A13: NT-1012 | B13: Isha Mehta | C13: isha.mehta@nimbustech.example | D13: AI Lab | E13: Senior ML Engineer | F13: L3 | G13: Mohan Iyer | H13: 44477 | I13: 5 | J13: Bengaluru | K13: Remote | L13: Contract | M13: B.E. Computer Science | N13: Python (L5), Machine Learning (L5), Docker & Kubernetes (L3) | O13: Data Analytics (L3), Cloud Computing (AWS/Azure) (L2) | P13: PCEP - Certified Entry-Level Python Programmer | Q13: 4 | R13: 40 | S13: =SUMIFS(Allocations!$G$2:$G$274,Allocations!$B$2:$B$274,A13) -> 32 | T13: =S13/R13 -> 0.8 | U13: =R13-S13 -> 8 | V13: =IF(T13>1,"Overloaded",IF(T13<0.5,"Underutilized","Healthy")) -> Healthy | W13: Retail Demand Forecasting (23h); Fintech Fraud Alerts (9h) | Z13: Modern React Patterns (May 2026)
A14: NT-1013 | B14: Naveen Sen | C14: naveen.sen@nimbustech.example | D14: Engineering | E14: Associate Full-Stack Developer | F14: L1 | G14: Charan Hegde | H14: 46229 | I14: 2 | J14: Pune | K14: Hybrid | L14: Full-time | M14: B.E. Electronics & Communication | N14: JavaScript (L4), React (L4), Node.js (L4) | O14: SQL (L2), Docker & Kubernetes (L2), Testing & QA (L2) | Q14: 3 | R14: 40 | S14: =SUMIFS(Allocations!$G$2:$G$274,Allocations!$B$2:$B$274,A14) -> 28 | T14: =S14/R14 -> 0.7 | U14: =R14-S14 -> 12 | V14: =IF(T14>1,"Overloaded",IF(T14<0.5,"Underutilized","Healthy")) -> Healthy | W14: Logistics Fleet Tracker App (7h); Hospital Appointment Portal (21h) | Z14: Python for Production Systems (Jan 2026)
A15: NT-1014 | B15: Aarav Teja | C15: aarav.teja@nimbustech.example | D15: Quality Assurance | E15: Principal QA Engineer | F15: L5 | G15: Rajesh Khanna (VP Delivery) | H15: 45209 | I15: 14 | J15: Bengaluru | K15: Hybrid | L15: Contract | M15: MCA | N15: Testing & QA (L4), JavaScript (L3), Python (L3) | O15: SQL (L2) | Q15: 2 | R15: 40 | S15: =SUMIFS(Allocations!$G$2:$G$274,Allocations!$B$2:$B$274,A15) -> 24 | T15: =S15/R15 -> 0.6 | U15: =R15-S15 -> 16 | V15: =IF(T15>1,"Overloaded",IF(T15<0.5,"Underutilized","Healthy")) -> Healthy | W15: Hospital Appointment Portal (9h); Fintech Fraud Alerts (15h) | Z15: Power BI Dashboard Design (May 2026)
A16: NT-1015 | B16: Imran Sheikh | C16: imran.sheikh@nimbustech.example | D16: Data & Analytics | E16: Data Scientist | F16: L2 | G16: Charan Jain | H16: 46167 | I16: 3 | J16: Mumbai | K16: Hybrid | L16: Full-time | M16: B.Sc Computer Science | N16: Python (L4), Machine Learning (L3), SQL (L3) | O16: Data Analytics (L3), Apache Spark (L2) | P16: PCEP - Certified Entry-Level Python Programmer | Q16: 3 | R16: 40 | S16: =SUMIFS(Allocations!$G$2:$G$274,Allocations!$B$2:$B$274,A16) -> 10 | T16: =S16/R16 -> 0.25 | U16: =R16-S16 -> 30 | V16: =IF(T16>1,"Overloaded",IF(T16<0.5,"Underutilized","Healthy")) -> Underutilized | W16: Retail Demand Forecasting (10h) | Z16: Data Analytics with Python and SQL (May 2026)
A17: NT-1016 | B17: Disha Iyer | C17: disha.iyer@nimbustech.example | D17: Engineering | E17: Senior Backend Engineer | F17: L3 | G17: Charan Hegde | H17: 44602 | I17: 5 | J17: Hyderabad | K17: Hybrid | L17: Full-time | M17: M.Tech Computer Science | N17: Python (L5), SQL (L4), Cloud Computing (AWS/Azure) (L4) | O17: Node.js (L2), Docker & Kubernetes (L2), Testing & QA (L2) | P17: PCEP - Certified Entry-Level Python Programmer; Oracle SQL Associate; Microsoft Azure Fundamentals (AZ-900) | Q17: 3 | R17: 40 | S17: =SUMIFS(Allocations!$G$2:$G$274,Allocations!$B$2:$B$274,A17) -> 28 | T17: =S17/R17 -> 0.7 | U17: =R17-S17 -> 12 | V17: =IF(T17>1,"Overloaded",IF(T17<0.5,"Underutilized","Healthy")) -> Healthy | W17: Retail Demand Forecasting (7h); Cloud Migration - Legacy ERP (5h); Logistics Fleet Tracker App (16h)
A18: NT-1017 | B18: Keerthi Nambiar | C18: keerthi.nambiar@nimbustech.example | D18: AI Lab | E18: Associate ML Engineer | F18: L1 | G18: Mohan Iyer | H18: 45727 | I18: 1 | J18: Bengaluru | K18: Onsite | L18: Full-time | M18: B.E. Computer Science | N18: Machine Learning (L5), Python (L4), Docker & Kubernetes (L4) | O18: Cloud Computing (AWS/Azure) (L3), Data Analytics (L3) | P18: TensorFlow Developer Certificate; PCEP - Certified Entry-Level Python Programmer; Certified Kubernetes Administrator (CKA) | Q18: 4 | R18: 40 | S18: =SUMIFS(Allocations!$G$2:$G$274,Allocations!$B$2:$B$274,A18) -> 36 | T18: =S18/R18 -> 0.9 | U18: =R18-S18 -> 4 | V18: =IF(T18>1,"Overloaded",IF(T18<0.5,"Underutilized","Healthy")) -> Healthy | W18: Retail Demand Forecasting (23h); Fintech Fraud Alerts (13h) | Z18: Applied Machine Learning (May 2026)
A19: NT-1018 | B19: Karthik Ghosh | C19: karthik.ghosh@nimbustech.example | D19: Design | E19: Lead UI/UX Designer | F19: L4 | G19: Priya Teja | H19: 43120 | I19: 10 | J19: Bengaluru | K19: Hybrid | L19: Full-time | M19: B.E. Electronics & Communication | N19: UI/UX Design (L5), JavaScript (L3), React (L2) | O19: DevOps & CI/CD (L1) | Q19: 3 | R19: 40 | S19: =SUMIFS(Allocations!$G$2:$G$274,Allocations!$B$2:$B$274,A19) -> 36 | T19: =S19/R19 -> 0.9 | U19: =R19-S19 -> 4 | V19: =IF(T19>1,"Overloaded",IF(T19<0.5,"Underutilized","Healthy")) -> Healthy | W19: Hospital Appointment Portal (23h); Logistics Fleet Tracker App (13h) | Z19: Apache Spark Essentials for Data Engineers (Aug 2026)
A20: NT-1019 | B20: Usha Khan | C20: usha.khan@nimbustech.example | D20: Engineering | E20: Associate Full-Stack Developer | F20: L1 | G20: Charan Hegde | H20: 45945 | I20: 1 | J20: Chennai | K20: Hybrid | L20: Full-time | M20: M.Tech Computer Science | N20: React (L4), SQL (L4), JavaScript (L3) | O20: Node.js (L3), Docker & Kubernetes (L3) | P20: Oracle SQL Associate | Q20: 3 | R20: 40 | S20: =SUMIFS(Allocations!$G$2:$G$274,Allocations!$B$2:$B$274,A20) -> 28 | T20: =S20/R20 -> 0.7 | U20: =R20-S20 -> 12 | V20: =IF(T20>1,"Overloaded",IF(T20<0.5,"Underutilized","Healthy")) -> Healthy | W20: Hospital Appointment Portal (6h); Logistics Fleet Tracker App (4h); Retail Demand Forecasting (18h) | Z20: Modern React Patterns (May 2026)
A21: NT-1020 | B21: Ritika Naik | C21: ritika.naik@nimbustech.example | D21: Platform | E21: Senior DevOps Engineer | F21: L3 | G21: Pooja Narayan | H21: 45452 | I21: 6 | J21: Bengaluru | K21: Hybrid | L21: Contract | M21: B.E. Information Science | N21: DevOps & CI/CD (L5), Docker & Kubernetes (L3), Cloud Computing (AWS/Azure) (L3) | O21: Cybersecurity (L3), Python (L2), JavaScript (L2) | Q21: 3 | R21: 40 | S21: =SUMIFS(Allocations!$G$2:$G$274,Allocations!$B$2:$B$274,A21) -> 16 | T21: =S21/R21 -> 0.4 | U21: =R21-S21 -> 24 | V21: =IF(T21>1,"Overloaded",IF(T21<0.5,"Underutilized","Healthy")) -> Underutilized | W21: Cloud Migration - Legacy ERP (16h) | Z21: Secure Cloud Engineering (Jul 2026)
A22: NT-1021 | B22: Chetan Sen | C22: chetan.sen@nimbustech.example | D22: Engineering | E22: Lead Full-Stack Developer | F22: L4 | G22: Charan Hegde | H22: 46100 | I22: 9 | J22: Bengaluru | K22: Hybrid | L22: Full-time | M22: B.E. Electronics & Communication | N22: Node.js (L5), React (L4), JavaScript (L3) | O22: SQL (L3), Docker & Kubernetes (L2), Data Analytics (L1) | Q22: 3 | R22: 40 | S22: =SUMIFS(Allocations!$G$2:$G$274,Allocations!$B$2:$B$274,A22) -> 28 | T22: =S22/R22 -> 0.7 | U22: =R22-S22 -> 12 | V22: =IF(T22>1,"Overloaded",IF(T22<0.5,"Underutilized","Healthy")) -> Healthy | W22: Logistics Fleet Tracker App (9h); Hospital Appointment Portal (7h); HR Analytics Dashboard (12h) | Z22: Power BI Dashboard Design (Aug 2026)
A23: NT-1022 | B23: Lakshmi Chauhan | C23: lakshmi.chauhan@nimbustech.example | D23: Engineering | E23: Senior Backend Engineer | F23: L3 | G23: Charan Hegde | H23: 45212 | I23: 5 | J23: Bengaluru | K23: Remote | L23: Full-time | M23: B.Sc Computer Science | N23: Python (L4), SQL (L4), Node.js (L4) | O23: Cloud Computing (AWS/Azure) (L3), Docker & Kubernetes (L2), Testing & QA (L2) | Q23: 3 | R23: 40 | S23: =SUMIFS(Allocations!$G$2:$G$274,Allocations!$B$2:$B$274,A23) -> 34 | T23: =S23/R23 -> 0.85 | U23: =R23-S23 -> 6 | V23: =IF(T23>1,"Overloaded",IF(T23<0.5,"Underutilized","Healthy")) -> Healthy | W23: Hospital Appointment Portal (15h); Logistics Fleet Tracker App (19h) | Z23: TypeScript for JavaScript Developers (Aug 2026)
A24: NT-1023 | B24: Suresh Prasad | C24: suresh.prasad@nimbustech.example | D24: AI Lab | E24: Senior ML Engineer | F24: L3 | G24: Mohan Iyer | H24: 44093 | I24: 7 | J24: Hyderabad | K24: Onsite | L24: Full-time | M24: B.E. Computer Science | N24: Python (L4), Machine Learning (L4), Cloud Computing (AWS/Azure) (L4) | O24: Docker & Kubernetes (L3), Data Analytics (L3), JavaScript (L1) | P24: PCEP - Certified Entry-Level Python Programmer | Q24: 5 | R24: 40 | S24: =SUMIFS(Allocations!$G$2:$G$274,Allocations!$B$2:$B$274,A24) -> 26 | T24: =S24/R24 -> 0.65 | U24: =R24-S24 -> 14 | V24: =IF(T24>1,"Overloaded",IF(T24<0.5,"Underutilized","Healthy")) -> Healthy | W24: Retail Demand Forecasting (20h); Fintech Fraud Alerts (6h) | Z24: Advanced Analytics and Storytelling (Mar 2026)
A25: NT-1024 | B25: Harini Gupta | C25: harini.gupta@nimbustech.example | D25: Engineering | E25: Senior Full-Stack Developer | F25: L3 | G25: Charan Hegde | H25: 44259 | I25: 5 | J25: Bengaluru | K25: Hybrid | L25: Full-time | M25: B.E. Computer Science | N25: React (L5), JavaScript (L4), Node.js (L3) | O25: SQL (L3), Docker & Kubernetes (L3) | Q25: 4 | R25: 40 | S25: =SUMIFS(Allocations!$G$2:$G$274,Allocations!$B$2:$B$274,A25) -> 46 | T25: =S25/R25 -> 1.15 | U25: =R25-S25 -> -6 | V25: =IF(T25>1,"Overloaded",IF(T25<0.5,"Underutilized","Healthy")) -> Overloaded | W25: Logistics Fleet Tracker App (30h); Hospital Appointment Portal (10h); Cloud Migration - Legacy ERP (6h) | Z25: Advanced Analytics and Storytelling (Aug 2026)
A26: NT-1025 | B26: Venkat Kulkarni | C26: venkat.kulkarni@nimbustech.example | D26: Engineering | E26: Frontend Developer | F26: L2 | G26: Charan Hegde | H26: 45025 | I26: 3 | J26: Bengaluru | K26: Hybrid | L26: Full-time | M26: B.E. Computer Science | N26: React (L5), JavaScript (L4), UI/UX Design (L2) | O26: Testing & QA (L2) | Q26: 4 | R26: 40 | S26: =SUMIFS(Allocations!$G$2:$G$274,Allocations!$B$2:$B$274,A26) -> 26 | T26: =S26/R26 -> 0.65 | U26: =R26-S26 -> 14 | V26: =IF(T26>1,"Overloaded",IF(T26<0.5,"Underutilized","Healthy")) -> Healthy | W26: Logistics Fleet Tracker App (18h); Hospital Appointment Portal (8h) | Z26: Design Systems for Product Teams (Feb 2026)
A27: NT-1026 | B27: Gautham Iyer | C27: gautham.iyer@nimbustech.example | D27: AI Lab | E27: Associate ML Engineer | F27: L1 | G27: Mohan Iyer | H27: 45548 | I27: 2 | J27: Bengaluru | K27: Onsite | L27: Full-time | M27: M.Tech Computer Science | N27: Python (L5), Machine Learning (L4), Cloud Computing (AWS/Azure) (L4) | O27: Data Analytics (L4), Docker & Kubernetes (L2), JavaScript (L2) | P27: Databricks ML Associate; AWS Certified Solutions Architect - Associate; Google Data Analytics Certificate | Q27: 5 | R27: 40 | S27: =SUMIFS(Allocations!$G$2:$G$274,Allocations!$B$2:$B$274,A27) -> 44 | T27: =S27/R27 -> 1.1 | U27: =R27-S27 -> -4 | V27: =IF(T27>1,"Overloaded",IF(T27<0.5,"Underutilized","Healthy")) -> Overloaded | W27: Retail Demand Forecasting (4h); Fintech Fraud Alerts (6h); Logistics Fleet Tracker App (34h) | Z27: Advanced SQL for Analysts (Apr 2026)
A28: NT-1027 | B28: Venkat Reddy | C28: venkat.reddy@nimbustech.example | D28: Engineering | E28: Associate Frontend Developer | F28: L1 | G28: Charan Hegde | H28: 45328 | I28: 2 | J28: Chennai | K28: Onsite | L28: Full-time | M28: B.Sc Computer Science | N28: React (L5), UI/UX Design (L4), Testing & QA (L4) | O28: JavaScript (L3) | P28: ISTQB Foundation Level | Q28: 3 | R28: 40 | S28: =SUMIFS(Allocations!$G$2:$G$274,Allocations!$B$2:$B$274,A28) -> 24 | T28: =S28/R28 -> 0.6 | U28: =R28-S28 -> 16 | V28: =IF(T28>1,"Overloaded",IF(T28<0.5,"Underutilized","Healthy")) -> Healthy | W28: Hospital Appointment Portal (19h); Logistics Fleet Tracker App (5h) | X28: 46341 | Y28: 46346 | Z28: Advanced Analytics and Storytelling (Sep 2026)
A29: NT-1028 | B29: Vikram Nair | C29: vikram.nair@nimbustech.example | D29: Engineering | E29: Lead Frontend Developer | F29: L4 | G29: Charan Hegde | H29: 44087 | I29: 9 | J29: Hyderabad | K29: Hybrid | L29: Contract | M29: B.E. Computer Science | N29: JavaScript (L5), React (L5), Testing & QA (L3) | O29: UI/UX Design (L2), SQL (L1) | Q29: 5 | R29: 40 | S29: =SUMIFS(Allocations!$G$2:$G$274,Allocations!$B$2:$B$274,A29) -> 36 | T29: =S29/R29 -> 0.9 | U29: =R29-S29 -> 4 | V29: =IF(T29>1,"Overloaded",IF(T29<0.5,"Underutilized","Healthy")) -> Healthy | W29: Hospital Appointment Portal (5h); Logistics Fleet Tracker App (31h)
A30: NT-1029 | B30: Anjali Reddy | C30: anjali.reddy@nimbustech.example | D30: Engineering | E30: Senior Backend Engineer | F30: L3 | G30: Charan Hegde | H30: 44700 | I30: 5 | J30: Bengaluru | K30: Hybrid | L30: Full-time | M30: MCA | N30: SQL (L5), Node.js (L4), Docker & Kubernetes (L4) | O30: Python (L3), Cloud Computing (AWS/Azure) (L3), Testing & QA (L3), Data Analytics (L1) | P30: Oracle SQL Associate; Certified Kubernetes Administrator (CKA) | Q30: 3 | R30: 40 | S30: =SUMIFS(Allocations!$G$2:$G$274,Allocations!$B$2:$B$274,A30) -> 32 | T30: =S30/R30 -> 0.8 | U30: =R30-S30 -> 8 | V30: =IF(T30>1,"Overloaded",IF(T30<0.5,"Underutilized","Healthy")) -> Healthy | W30: Hospital Appointment Portal (12h); Logistics Fleet Tracker App (20h) | Z30: Apache Spark Essentials for Data Engineers (Feb 2026)
A31: NT-1030 | B31: Farhan Shenoy | C31: farhan.shenoy@nimbustech.example | D31: Engineering | E31: Senior Full-Stack Developer | F31: L3 | G31: Charan Hegde | H31: 44465 | I31: 7 | J31: Bengaluru | K31: Onsite | L31: Full-time | M31: B.E. Information Science | N31: JavaScript (L4), React (L4), SQL (L4) | O31: Node.js (L3), Data Analytics (L2), Docker & Kubernetes (L1) | Q31: 5 | R31: 40 | S31: =SUMIFS(Allocations!$G$2:$G$274,Allocations!$B$2:$B$274,A31) -> 36 | T31: =S31/R31 -> 0.9 | U31: =R31-S31 -> 4 | V31: =IF(T31>1,"Overloaded",IF(T31<0.5,"Underutilized","Healthy")) -> Healthy | W31: Logistics Fleet Tracker App (26h); Hospital Appointment Portal (10h) | Z31: Spark Performance Tuning (Jul 2026)
A32: NT-1031 | B32: Divya Kulkarni | C32: divya.kulkarni@nimbustech.example | D32: Engineering | E32: Lead Full-Stack Developer | F32: L4 | G32: Charan Hegde | H32: 45558 | I32: 9 | J32: Bengaluru | K32: Onsite | L32: Full-time | M32: B.Sc Computer Science | N32: JavaScript (L5), React (L4), Node.js (L3) | O32: SQL (L2), Docker & Kubernetes (L2), Machine Learning (L2) | Q32: 2 | R32: 40 | S32: =SUMIFS(Allocations!$G$2:$G$274,Allocations!$B$2:$B$274,A32) -> 24 | T32: =S32/R32 -> 0.6 | U32: =R32-S32 -> 16 | V32: =IF(T32>1,"Overloaded",IF(T32<0.5,"Underutilized","Healthy")) -> Healthy | W32: Logistics Fleet Tracker App (17h); Hospital Appointment Portal (7h) | X32: 46344 | Y32: 46348 | Z32: Apache Spark Essentials for Data Engineers (May 2026)
A33: NT-1032 | B33: Ritika Sheikh | C33: ritika.sheikh@nimbustech.example | D33: Quality Assurance | E33: QA Engineer | F33: L2 | G33: Aarav Teja | H33: 44968 | I33: 3 | J33: Bengaluru | K33: Hybrid | L33: Full-time | M33: B.E. Electronics & Communication | N33: Testing & QA (L5), JavaScript (L3), SQL (L2) | P33: ISTQB Foundation Level | Q33: 4 | R33: 40 | S33: =SUMIFS(Allocations!$G$2:$G$274,Allocations!$B$2:$B$274,A33) -> 36 | T33: =S33/R33 -> 0.9 | U33: =R33-S33 -> 4 | V33: =IF(T33>1,"Overloaded",IF(T33<0.5,"Underutilized","Healthy")) -> Healthy | W33: Hospital Appointment Portal (6h); Logistics Fleet Tracker App (16h); Retail Demand Forecasting (14h) | Z33: CI/CD Pipelines with GitHub Actions (Dec 2025)
A34: NT-1033 | B34: Meera Bhandari | C34: meera.bhandari@nimbustech.example | D34: Delivery | E34: Director - Project Manager | F34: L5 | G34: Rajesh Khanna (VP Delivery) | H34: 44273 | I34: 14 | J34: Bengaluru | K34: Hybrid | L34: Contract | M34: B.E. Electronics & Communication | N34: Project Management (L5), Power BI / Tableau (L3), Data Analytics (L1) | Q34: 5 | R34: 40 | S34: =SUMIFS(Allocations!$G$2:$G$274,Allocations!$B$2:$B$274,A34) -> 36 | T34: =S34/R34 -> 0.9 | U34: =R34-S34 -> 4 | V34: =IF(T34>1,"Overloaded",IF(T34<0.5,"Underutilized","Healthy")) -> Healthy | W34: HR Analytics Dashboard (13h); Logistics Fleet Tracker App (18h); Retail Demand Forecasting (5h) | Z34: Kubernetes in Practice (Jun 2026)
A35: NT-1034 | B35: Venkat Prasad | C35: venkat.prasad@nimbustech.example | D35: Platform | E35: Lead DevOps Engineer | F35: L4 | G35: Pooja Narayan | H35: 44075 | I35: 9 | J35: Bengaluru | K35: Hybrid | L35: Full-time | M35: B.E. Computer Science | N35: DevOps & CI/CD (L5), Cloud Computing (AWS/Azure) (L5), Docker & Kubernetes (L4) | O35: Python (L3), Cybersecurity (L3), Testing & QA (L1) | Q35: 3 | R35: 40 | S35: =SUMIFS(Allocations!$G$2:$G$274,Allocations!$B$2:$B$274,A35) -> 28 | T35: =S35/R35 -> 0.7 | U35: =R35-S35 -> 12 | V35: =IF(T35>1,"Overloaded",IF(T35<0.5,"Underutilized","Healthy")) -> Healthy | W35: Cloud Migration - Legacy ERP (5h); Fintech Fraud Alerts (19h); Retail Demand Forecasting (4h) | Z35: Advanced Analytics and Storytelling (Jul 2026)
A36: NT-1035 | B36: Meera Iyer | C36: meera.iyer@nimbustech.example | D36: Data & Analytics | E36: Senior Data Analyst | F36: L3 | G36: Charan Jain | H36: 45061 | I36: 6 | J36: Bengaluru | K36: Onsite | L36: Full-time | M36: B.E. Information Science | N36: SQL (L5), Power BI / Tableau (L5), Data Analytics (L4) | O36: Python (L3) | P36: Oracle SQL Associate | Q36: 4 | R36: 40 | S36: =SUMIFS(Allocations!$G$2:$G$274,Allocations!$B$2:$B$274,A36) -> 22 | T36: =S36/R36 -> 0.55 | U36: =R36-S36 -> 18 | V36: =IF(T36>1,"Overloaded",IF(T36<0.5,"Underutilized","Healthy")) -> Healthy | W36: HR Analytics Dashboard (22h) | Z36: Python Fundamentals Bootcamp (Mar 2026)
A37: NT-1036 | B37: Eshwar Reddy | C37: eshwar.reddy@nimbustech.example | D37: Design | E37: Lead UI/UX Designer | F37: L4 | G37: Priya Teja | H37: 43937 | I37: 10 | J37: Bengaluru | K37: Onsite | L37: Full-time | M37: B.E. Computer Science | N37: UI/UX Design (L5), React (L2), JavaScript (L1) | O37: Machine Learning (L1) | Q37: 5 | R37: 40 | S37: =SUMIFS(Allocations!$G$2:$G$274,Allocations!$B$2:$B$274,A37) -> 36 | T37: =S37/R37 -> 0.9 | U37: =R37-S37 -> 4 | V37: =IF(T37>1,"Overloaded",IF(T37<0.5,"Underutilized","Healthy")) -> Healthy | W37: Hospital Appointment Portal (19h); Logistics Fleet Tracker App (17h) | Z37: Cloud Solutions Architect Prep (Jul 2026)
A38: NT-1037 | B38: Eshwar Rajan | C38: eshwar.rajan@nimbustech.example | D38: Platform | E38: DevOps Engineer | F38: L2 | G38: Pooja Narayan | H38: 44917 | I38: 3 | J38: Bengaluru | K38: Onsite | L38: Full-time | M38: B.E. Information Science | N38: DevOps & CI/CD (L5), Cloud Computing (AWS/Azure) (L5), Python (L4) | O38: Docker & Kubernetes (L3), Cybersecurity (L3) | P38: HashiCorp Terraform Associate | Q38: 3 | R38: 40 | S38: =SUMIFS(Allocations!$G$2:$G$274,Allocations!$B$2:$B$274,A38) -> 30 | T38: =S38/R38 -> 0.75 | U38: =R38-S38 -> 10 | V38: =IF(T38>1,"Overloaded",IF(T38<0.5,"Underutilized","Healthy")) -> Healthy | W38: Cloud Migration - Legacy ERP (16h); Fintech Fraud Alerts (14h) | Z38: Modern React Patterns (Jun 2026)
A39: NT-1038 | B39: Pranav Bhat | C39: pranav.bhat@nimbustech.example | D39: Platform | E39: DevOps Engineer | F39: L2 | G39: Pooja Narayan | H39: 45719 | I39: 3 | J39: Chennai | K39: Hybrid | L39: Full-time | M39: MCA | N39: DevOps & CI/CD (L5), Docker & Kubernetes (L5), Cloud Computing (AWS/Azure) (L5) | O39: Python (L2), Cybersecurity (L2), Machine Learning (L2) | P39: AWS Certified Solutions Architect - Associate | Q39: 5 | R39: 40 | S39: =SUMIFS(Allocations!$G$2:$G$274,Allocations!$B$2:$B$274,A39) -> 32 | T39: =S39/R39 -> 0.8 | U39: =R39-S39 -> 8 | V39: =IF(T39>1,"Overloaded",IF(T39<0.5,"Underutilized","Healthy")) -> Healthy | W39: Cloud Migration - Legacy ERP (24h); Logistics Fleet Tracker App (8h) | Z39: Cloud Architecture Essentials (AWS/Azure) (Apr 2026)
A40: NT-1039 | B40: Sowmya Kamath | C40: sowmya.kamath@nimbustech.example | D40: Delivery | E40: Director - Project Manager | F40: L5 | G40: Meera Bhandari | H40: 45467 | I40: 14 | J40: Bengaluru | K40: Remote | L40: Full-time | M40: B.Sc Computer Science | N40: Project Management (L4), Power BI / Tableau (L3), DevOps & CI/CD (L2) | O40: Data Analytics (L1) | P40: Certified ScrumMaster (CSM) | Q40: 3 | R40: 40 | S40: =SUMIFS(Allocations!$G$2:$G$274,Allocations!$B$2:$B$274,A40) -> 36 | T40: =S40/R40 -> 0.9 | U40: =R40-S40 -> 4 | V40: =IF(T40>1,"Overloaded",IF(T40<0.5,"Underutilized","Healthy")) -> Healthy | W40: HR Analytics Dashboard (31h); Fintech Fraud Alerts (5h) | Z40: Agile Delivery and Risk Management (May 2026)
...

Sheet Skill_Matrix
A1: Employee ID | B1: Full Name | C1: Python | D1: JavaScript | E1: React | F1: Node.js | G1: SQL | H1: Cloud Computing (AWS/Azure) | I1: Docker & Kubernetes | J1: DevOps & CI/CD | K1: Data Analytics | L1: Power BI / Tableau | M1: Machine Learning | N1: Apache Spark | O1: UI/UX Design | P1: Testing & QA | Q1: Project Management | R1: Cybersecurity
A2: NT-1001 | B2: Pooja Mishra | D2: 2 | G2: 3 | P2: 5
A3: NT-1002 | B3: Varun Teja | D3: 3 | G3: 2 | P3: 5
A4: NT-1003 | B4: Nithya Kamath | D4: 3 | E4: 5 | O4: 4 | P4: 3
A5: NT-1004 | B5: Akash Jain | D5: 5 | E5: 5 | O5: 3 | P5: 3
A6: NT-1005 | B6: Harsha Kapoor | D6: 5 | E6: 5 | F6: 5 | G6: 3 | I6: 2 | J6: 2
A7: NT-1006 | B7: Naveen Prasad | C7: 2 | H7: 4 | I7: 4 | J7: 5 | K7: 2 | R7: 4
A8: NT-1007 | B8: Pallavi Tiwari | C8: 3 | F8: 3 | G8: 3 | H8: 3 | I8: 2 | L8: 2 | P8: 1
A9: NT-1008 | B9: Uday Shenoy | D9: 5 | E9: 5 | M9: 2 | O9: 3 | P9: 3
A10: NT-1009 | B10: Pooja Narayan | C10: 2 | H10: 3 | I10: 3 | J10: 5 | R10: 3
A11: NT-1010 | B11: Charan Hegde | C11: 3 | F11: 4 | G11: 3 | H11: 2 | I11: 3 | P11: 2
A12: NT-1011 | B12: Divya Menon | C12: 4 | G12: 4 | K12: 4 | L12: 3 | M12: 3
A13: NT-1012 | B13: Isha Mehta | C13: 5 | H13: 2 | I13: 3 | K13: 3 | M13: 5
A14: NT-1013 | B14: Naveen Sen | D14: 4 | E14: 4 | F14: 4 | G14: 2 | I14: 2 | P14: 2
A15: NT-1014 | B15: Aarav Teja | C15: 3 | D15: 3 | G15: 2 | P15: 4
A16: NT-1015 | B16: Imran Sheikh | C16: 4 | G16: 3 | K16: 3 | M16: 3 | N16: 2
A17: NT-1016 | B17: Disha Iyer | C17: 5 | F17: 2 | G17: 4 | H17: 4 | I17: 2 | P17: 2
A18: NT-1017 | B18: Keerthi Nambiar | C18: 4 | H18: 3 | I18: 4 | K18: 3 | M18: 5
A19: NT-1018 | B19: Karthik Ghosh | D19: 3 | E19: 2 | J19: 1 | O19: 5
A20: NT-1019 | B20: Usha Khan | D20: 3 | E20: 4 | F20: 3 | G20: 4 | I20: 3
A21: NT-1020 | B21: Ritika Naik | C21: 2 | D21: 2 | H21: 3 | I21: 3 | J21: 5 | R21: 3
A22: NT-1021 | B22: Chetan Sen | D22: 3 | E22: 4 | F22: 5 | G22: 3 | I22: 2 | K22: 1
A23: NT-1022 | B23: Lakshmi Chauhan | C23: 4 | F23: 4 | G23: 4 | H23: 3 | I23: 2 | P23: 2
A24: NT-1023 | B24: Suresh Prasad | C24: 4 | D24: 1 | H24: 4 | I24: 3 | K24: 3 | M24: 4
A25: NT-1024 | B25: Harini Gupta | D25: 4 | E25: 5 | F25: 3 | G25: 3 | I25: 3
A26: NT-1025 | B26: Venkat Kulkarni | D26: 4 | E26: 5 | O26: 2 | P26: 2
A27: NT-1026 | B27: Gautham Iyer | C27: 5 | D27: 2 | H27: 4 | I27: 2 | K27: 4 | M27: 4
A28: NT-1027 | B28: Venkat Reddy | D28: 3 | E28: 5 | O28: 4 | P28: 4
A29: NT-1028 | B29: Vikram Nair | D29: 5 | E29: 5 | G29: 1 | O29: 2 | P29: 3
A30: NT-1029 | B30: Anjali Reddy | C30: 3 | F30: 4 | G30: 5 | H30: 3 | I30: 4 | K30: 1 | P30: 3
A31: NT-1030 | B31: Farhan Shenoy | D31: 4 | E31: 4 | F31: 3 | G31: 4 | I31: 1 | K31: 2
A32: NT-1031 | B32: Divya Kulkarni | D32: 5 | E32: 4 | F32: 3 | G32: 2 | I32: 2 | M32: 2
A33: NT-1032 | B33: Ritika Sheikh | D33: 3 | G33: 2 | P33: 5
A34: NT-1033 | B34: Meera Bhandari | K34: 1 | L34: 3 | Q34: 5
A35: NT-1034 | B35: Venkat Prasad | C35: 3 | H35: 5 | I35: 4 | J35: 5 | P35: 1 | R35: 3
A36: NT-1035 | B36: Meera Iyer | C36: 3 | G36: 5 | K36: 4 | L36: 5
A37: NT-1036 | B37: Eshwar Reddy | D37: 1 | E37: 2 | M37: 1 | O37: 5
A38: NT-1037 | B38: Eshwar Rajan | C38: 4 | H38: 5 | I38: 3 | J38: 5 | R38: 3
A39: NT-1038 | B39: Pranav Bhat | C39: 2 | H39: 5 | I39: 5 | J39: 5 | M39: 2 | R39: 2
A40: NT-1039 | B40: Sowmya Kamath | J40: 2 | K40: 1 | L40: 3 | Q40: 4
...

Sheet Allocations
A1: Allocation ID | B1: Employee ID | C1: Employee | D1: Project ID | E1: Project | F1: Task | G1: Hours/Week | H1: Priority | I1: Movable
A2: AL-0001 | B2: NT-1001 | C2: Pooja Mishra | D2: P2 | E2: Hospital Appointment Portal | F2: Booking flow UI | G2: 15 | H2: Low | I2: Yes
A3: AL-0002 | B3: NT-1001 | C3: Pooja Mishra | D3: P5 | E3: HR Analytics Dashboard | F3: KPI dashboards | G3: 17 | H3: High | I3: Yes
A4: AL-0003 | B4: NT-1002 | C4: Varun Teja | D4: P2 | E4: Hospital Appointment Portal | F4: Booking flow UI | G4: 21 | H4: Low | I4: Yes
A5: AL-0004 | B5: NT-1002 | C5: Varun Teja | D5: P4 | E5: Logistics Fleet Tracker App | F5: Telemetry ingestion | G5: 13 | H5: High | I5: Yes
A6: AL-0005 | B6: NT-1003 | C6: Nithya Kamath | D6: P2 | E6: Hospital Appointment Portal | F6: Booking flow UI | G6: 8 | H6: Medium | I6: Yes
A7: AL-0006 | B7: NT-1003 | C7: Nithya Kamath | D7: P4 | E7: Logistics Fleet Tracker App | F7: Telemetry ingestion | G7: 24 | H7: High | I7: No
A8: AL-0007 | B8: NT-1004 | C8: Akash Jain | D8: P2 | E8: Hospital Appointment Portal | F8: Slot scheduler API | G8: 5 | H8: Medium | I8: No
A9: AL-0008 | B9: NT-1004 | C9: Akash Jain | D9: P4 | E9: Logistics Fleet Tracker App | F9: Map view | G9: 19 | H9: High | I9: No
A10: AL-0009 | B10: NT-1005 | C10: Harsha Kapoor | D10: P4 | E10: Logistics Fleet Tracker App | F10: Map view | G10: 17 | H10: High | I10: No
A11: AL-0010 | B11: NT-1005 | C11: Harsha Kapoor | D11: P2 | E11: Hospital Appointment Portal | F11: Auth service | G11: 17 | H11: Medium | I11: Yes
A12: AL-0011 | B12: NT-1006 | C12: Naveen Prasad | D12: P6 | E12: Cloud Migration - Legacy ERP | F12: Infra as code | G12: 10 | H12: High | I12: Yes
A13: AL-0012 | B13: NT-1006 | C13: Naveen Prasad | D13: P3 | E13: Fintech Fraud Alerts | F13: Alert rules engine | G13: 6 | H13: Low | I13: Yes
... A274: AL-0273 | B274: NT-1120 | C274: Chetan Nair | D274: P1 | E274: Retail Demand Forecasting | F274: Forecast API | G274: 22 | H274: High | I274: Yes

Sheet Projects
A1: Project ID | B1: Project | C1: Client | D1: Description | E1: Status | F1: Start Date | G1: Deadline | H1: Priority | I1: Assigned People | J1: Assigned Hrs/Week
A2: P1 | B2: Retail Demand Forecasting | C2: UrbanKart | D2: ML forecasting for store-level demand. | E2: Active | F2: 46237 | G2: 46374 | H2: High | I2: =COUNTIFS(Allocations!$D$2:$D$274,A2) -> 60 | J2: =SUMIFS(Allocations!$G$2:$G$274,Allocations!$D$2:$D$274,A2) -> 741
A3: P2 | B3: Hospital Appointment Portal | C3: CarePoint Health | D3: Patient booking web app. | E3: Active | F3: 46216 | G3: 46353 | H3: Medium | I3: =COUNTIFS(Allocations!$D$2:$D$274,A3) -> 64 | J3: =SUMIFS(Allocations!$G$2:$G$274,Allocations!$D$2:$D$274,A3) -> 764
A4: P3 | B4: Fintech Fraud Alerts | C4: PayNova | D4: Real-time transaction anomaly alerts. | E4: Active | F4: 46266 | G4: 46402 | H4: High | I4: =COUNTIFS(Allocations!$D$2:$D$274,A4) -> 32 | J4: =SUMIFS(Allocations!$G$2:$G$274,Allocations!$D$2:$D$274,A4) -> 374
A5: P4 | B5: Logistics Fleet Tracker App | C5: MoveFast Logistics | D5: Live fleet tracking web and mobile app. | E5: Active | F5: 46258 | G5: 46367 | H5: Medium | I5: =COUNTIFS(Allocations!$D$2:$D$274,A5) -> 62 | J5: =SUMIFS(Allocations!$G$2:$G$274,Allocations!$D$2:$D$274,A5) -> 931
A6: P5 | B6: HR Analytics Dashboard | C6: TalentBridge | D6: Attrition and hiring analytics dashboards. | E6: Active | F6: 46279 | G6: 46346 | H6: Medium | I6: =COUNTIFS(Allocations!$D$2:$D$274,A6) -> 32 | J6: =SUMIFS(Allocations!$G$2:$G$274,Allocations!$D$2:$D$274,A6) -> 457
A7: P6 | B7: Cloud Migration - Legacy ERP | C7: SteelWorks Ltd | D7: Lift and modernize on-prem ERP to cloud. | E7: Active | F7: 46195 | G7: 46416 | H7: High | I7: =COUNTIFS(Allocations!$D$2:$D$274,A7) -> 23 | J7: =SUMIFS(Allocations!$G$2:$G$274,Allocations!$D$2:$D$274,A7) -> 312
A8: P7 | B8: Customer Churn Analytics Platform | C8: TeleSure | D8: New project (Scenario A): churn prediction pipeline, cloud deployment, analytics dashboards. | E8: Planning | F8: 46328 | G8: 46444 | H8: High | I8: =COUNTIFS(Allocations!$D$2:$D$274,A8) -> 0 | J8: =SUMIFS(Allocations!$G$2:$G$274,Allocations!$D$2:$D$274,A8) -> 0

Sheet Project_Requirements
A1: Project ID | B1: Project | C1: Skill ID | D1: Skill | E1: Min Level | F1: Weight
A2: P1 | B2: Retail Demand Forecasting | C2: python | D2: Python | E2: 4 | F2: 0.3
A3: P1 | B3: Retail Demand Forecasting | C3: ml | D3: Machine Learning | E3: 4 | F3: 0.3
A4: P1 | B4: Retail Demand Forecasting | C4: sql | D4: SQL | E4: 3 | F4: 0.2
A5: P1 | B5: Retail Demand Forecasting | C5: cloud | D5: Cloud Computing (AWS/Azure) | E5: 3 | F5: 0.2
A6: P2 | B6: Hospital Appointment Portal | C6: react | D6: React | E6: 4 | F6: 0.27
A7: P2 | B7: Hospital Appointment Portal | C7: nodejs | D7: Node.js | E7: 4 | F7: 0.27
A8: P2 | B8: Hospital Appointment Portal | C8: sql | D8: SQL | E8: 3 | F8: 0.18
A9: P2 | B9: Hospital Appointment Portal | C9: uiux | D9: UI/UX Design | E9: 3 | F9: 0.18
A10: P2 | B10: Hospital Appointment Portal | C10: qa | D10: Testing & QA | E10: 3 | F10: 0.09
A11: P3 | B11: Fintech Fraud Alerts | C11: python | D11: Python | E11: 4 | F11: 0.3
A12: P3 | B12: Fintech Fraud Alerts | C12: ml | D12: Machine Learning | E12: 3 | F12: 0.2
A13: P3 | B13: Fintech Fraud Alerts | C13: cybersecurity | D13: Cybersecurity | E13: 4 | F13: 0.3
... A32: P7 | B32: Customer Churn Analytics Platform | C32: power_bi | D32: Power BI / Tableau | E32: 2 | F32: 0.05

Sheet Training_Catalog
A1: Course ID | B1: Course | C1: Skill ID | D1: Skill | E1: Level | F1: Duration (Hrs) | G1: Provider | H1: Mode
A2: T01 | B2: Python for Production Systems | C2: python | D2: Python | E2: Advanced | F2: 24 | G2: Coursera | H2: Self-paced
A3: T02 | B3: Python Fundamentals Bootcamp | C3: python | D3: Python | E3: Beginner | F3: 16 | G3: Udemy | H3: Instructor-led
A4: T03 | B4: Cloud Architecture Essentials (AWS/Azure) | C4: cloud | D4: Cloud Computing (AWS/Azure) | E4: Intermediate | F4: 20 | G4: LinkedIn Learning | H4: Self-paced
A5: T04 | B5: Cloud Solutions Architect Prep | C5: cloud | D5: Cloud Computing (AWS/Azure) | E5: Advanced | F5: 32 | G5: Internal Learning Hub | H5: Self-paced
A6: T05 | B6: Data Analytics with Python and SQL | C6: data_analytics | D6: Data Analytics | E6: Intermediate | F6: 18 | G6: Coursera | H6: Instructor-led
A7: T06 | B7: Advanced Analytics and Storytelling | C7: data_analytics | D7: Data Analytics | E7: Advanced | F7: 14 | G7: Udemy | H7: Self-paced
A8: T07 | B8: Apache Spark Essentials for Data Engineers | C8: spark | D8: Apache Spark | E8: Intermediate | F8: 18 | G8: LinkedIn Learning | H8: Instructor-led
A9: T08 | B9: Spark Performance Tuning | C9: spark | D9: Apache Spark | E9: Advanced | F9: 12 | G9: Internal Learning Hub | H9: Self-paced
A10: T09 | B10: Advanced SQL for Analysts | C10: sql | D10: SQL | E10: Intermediate | F10: 12 | G10: Coursera | H10: Self-paced
A11: T10 | B11: Power BI Dashboard Design | C11: power_bi | D11: Power BI / Tableau | E11: Intermediate | F11: 10 | G11: Udemy | H11: Instructor-led
A12: T11 | B12: Applied Machine Learning | C12: ml | D12: Machine Learning | E12: Intermediate | F12: 28 | G12: LinkedIn Learning | H12: Self-paced
A13: T12 | B13: Kubernetes in Practice | C13: docker_k8s | D13: Docker & Kubernetes | E13: Intermediate | F13: 16 | G13: Internal Learning Hub | H13: Instructor-led
... A21: T20 | B21: Agile Delivery and Risk Management | C21: project_mgmt | D21: Project Management | E21: Intermediate | F21: 10 | G21: Internal Learning Hub | H21: Self-paced

Sheet Skills
A1: Skill ID | B1: Skill | C1: Category
A2: python | B2: Python | C2: Programming
A3: javascript | B3: JavaScript | C3: Programming
A4: react | B4: React | C4: Frontend
A5: nodejs | B5: Node.js | C5: Backend
A6: sql | B6: SQL | C6: Data
A7: cloud | B7: Cloud Computing (AWS/Azure) | C7: Infrastructure
A8: docker_k8s | B8: Docker & Kubernetes | C8: Infrastructure
A9: devops | B9: DevOps & CI/CD | C9: Infrastructure
A10: data_analytics | B10: Data Analytics | C10: Data
A11: power_bi | B11: Power BI / Tableau | C11: Data
A12: ml | B12: Machine Learning | C12: AI
... A17: cybersecurity | B17: Cybersecurity | C17: Security
